<?xml version="1.0" encoding="utf-8"?>
<!-- This URDF was automatically created by SolidWorks to URDF Exporter! Originally created by Stephen Brawner (brawner@gmail.com) 
     Commit Version: 1.6.0-4-g7f85cfe  Build Version: 1.6.7995.38578
     For more information, please see http://wiki.ros.org/sw_urdf_exporter -->
<robot
  name="dog2">
  <link
    name="base">
    <inertial>
      <origin
        xyz="-0.012165 0.00021263 0.044979"
        rpy="0 0 0" />
      <mass
        value="4.829" />
      <inertia
        ixx="0.0064421"
        ixy="7.4367E-08"
        ixz="3.2353E-07"
        iyy="0.0077349"
        iyz="-7.7644E-07"
        izz="0.0064997" />
    </inertial>
    <visual>
      <origin
        xyz="0 0 0"
        rpy="0 0 0" />
      <geometry>
        <mesh
          filename="body_link.stl" />
      </geometry>
      <material
        name="">
        <color
          rgba="0.84706 0.84706 0.84706 1" />
      </material>
    </visual>
    <collision>
      <origin
        xyz="0 0 0"
        rpy="0 0 0" />
      <geometry>
        <mesh
          filename="body_link.stl" />
      </geometry>
    </collision>
  </link>
  <link
    name="FL_hip">
    <inertial>
      <origin
        xyz="0.00904833267309341 -0.000445723687959344 0.0509865906799308"
        rpy="0 0 0" />
      <mass
        value="0.676831582353488" />
      <inertia
        ixx="0.000670918912176583"
        ixy="-2.40217008915735E-06"
        ixz="-3.09955530519293E-08"
        iyy="0.000333023481994022"
        iyz="-6.92675414402724E-06"
        izz="0.000392733403154912" />
    </inertial>
    <visual>
      <origin
        xyz="0 0 0"
        rpy="0 0 0" />
      <geometry>
        <mesh
          filename="lf_link1.stl" />
      </geometry>
      <material
        name="">
        <color
          rgba="0.898039215686275 0.917647058823529 0.929411764705882 1" />
      </material>
    </visual>
    <collision>
      <origin
        xyz="0 0 0"
        rpy="0 0 0" />
      <geometry>
        <mesh
          filename="lf_link1.stl" />
      </geometry>
    </collision>
  </link>
  <joint
    name="FL_hip_joint"
    type="revolute">
    <origin
      xyz="0.18433 0.058364 0.045534"
      rpy="1.5708 0 1.5708" />
    <parent
      link="base" />
    <child
      link="FL_hip" />
    <axis
      xyz="0 0 1" />
    <limit
      lower="-3.14159"
      upper="3.14159"
      effort="23"
      velocity="30" />
  </joint>
  <link
    name="FL_thigh">
    <inertial>
      <origin
        xyz="0.0472514575966696 -0.000903641669833866 0.0548578566923584"
        rpy="0 0 0" />
      <mass
        value="1.40828092509435" />
      <inertia
        ixx="0.000745719651663519"
        ixy="-4.02219321491663E-05"
        ixz="7.1242873883565E-08"
        iyy="0.00271481952820581"
        iyz="8.28998702633984E-08"
        izz="0.00337840053075497" />
    </inertial>
    <visual>
      <origin
        xyz="0 0 0"
        rpy="0 0 0" />
      <geometry>
        <mesh
          filename="lf_link2.stl" />
      </geometry>
      <material
        name="">
        <color
          rgba="0.847058823529412 0.847058823529412 0.847058823529412 1" />
      </material>
    </visual>
    <collision>
      <origin
        xyz="0 0 0"
        rpy="0 0 0" />
      <geometry>
        <mesh
          filename="lf_link2.stl" />
      </geometry>
    </collision>
  </link>
  <joint
    name="FL_thigh_joint"
    type="revolute">
    <origin
      xyz="0.031298 0.00022929 0.06"
      rpy="-1.5708 0 -1.5708" />
    <parent
      link="FL_hip" />
    <child
      link="FL_thigh" />
    <axis
      xyz="0 0 1" />
    <limit
      lower="-3.14159"
      upper="3.14159"
      effort="23"
      velocity="30" />
  </joint>
  <link
    name="FL_calf">
    <inertial>
      <origin
        xyz="0.0837721792657498 -4.60194909956968E-09 0.000508787163328944"
        rpy="0 0 0" />
      <mass
        value="0.466427846899075" />
      <inertia
        ixx="0.000152426923926451"
        ixy="3.87195389140761E-13"
        ixz="-2.82057087422756E-19"
        iyy="0.0011385889216427"
        iyz="2.38040760326858E-19"
        izz="0.00126903700282227" />
    </inertial>
    <visual>
      <origin
        xyz="0 0 0"
        rpy="0 0 0" />
      <geometry>
        <mesh
          filename="lf_link3.stl" />
      </geometry>
      <material
        name="">
        <color
          rgba="0.847058823529412 0.847058823529412 0.847058823529412 1" />
      </material>
    </visual>
    <collision>
      <origin
        xyz="0 0 0"
        rpy="0 0 0" />
      <geometry>
        <mesh
          filename="lf_link3.stl" />
      </geometry>
    </collision>
  </link>
  <joint
    name="FL_calf_joint"
    type="revolute">
    <origin
      xyz="0.20707 -0.0041231 0.0716"
      rpy="0 0 -1.570796" />
    <parent
      link="FL_thigh" />
    <child
      link="FL_calf" />
    <axis
      xyz="0 0 1" />
    <limit
      lower="-3.14159"
      upper="3.14159"
      effort="23"
      velocity="30" />
  </joint>
  <link
    name="FL_foot">
    <inertial>
      <origin
        xyz="-3.50891271594378E-09 0.000378378703097815 -5.25715843080476E-09"
        rpy="0 0 0" />
      <mass
        value="0.084832216985374" />
      <inertia
        ixx="4.13433919259361E-05"
        ixy="3.33053354860391E-17"
        ixz="-6.88102277885596E-20"
        iyy="4.13555372031687E-05"
        iyz="-7.93938866707972E-21"
        izz="7.44813705583865E-05" />
    </inertial>
    <visual>
      <origin
        xyz="0 0 0"
        rpy="0 0 0" />
      <geometry>
        <mesh
          filename="lf_link4.stl" />
      </geometry>
      <material
        name="">
        <color
          rgba="1 1 1 1" />
      </material>
    </visual>
    <collision>
      <origin
        xyz="0 0 0"
        rpy="0 0 0" />
      <geometry>
        <mesh
          filename="lf_link4.stl" />
      </geometry>
    </collision>
  </link>
  <joint
    name="FL_foot_joint"
    type="fixed">
    <origin
      xyz="0.22 0 0.001"
      rpy="0 0 -1.5708" />
    <parent
      link="FL_calf" />
    <child
      link="FL_foot" />
    <axis
      xyz="0 0 0" />
  </joint>
  <link
    name="FR_hip">
    <inertial>
      <origin
        xyz="-0.00903401438885915 0.000387933700798641 0.051121762146726"
        rpy="0 0 0" />
      <mass
        value="0.677615723872956" />
      <inertia
        ixx="0.000670924721034683"
        ixy="-2.0825530197189E-06"
        ixz="-1.33910545242845E-07"
        iyy="0.000333055746247111"
        iyz="6.92566237298675E-06"
        izz="0.000392769912020416" />
    </inertial>
    <visual>
      <origin
        xyz="0 0 0"
        rpy="0 0 0" />
      <geometry>
        <mesh
          filename="rf_link1.stl" />
      </geometry>
      <material
        name="">
        <color
          rgba="0.898039215686275 0.917647058823529 0.929411764705882 1" />
      </material>
    </visual>
    <collision>
      <origin
        xyz="0 0 0"
        rpy="0 0 0" />
      <geometry>
        <mesh
          filename="rf_link1.stl" />
      </geometry>
    </collision>
  </link>
  <joint
    name="FR_hip_joint"
    type="revolute">
    <origin
      xyz="0.18643 -0.06136 0.03776"
      rpy="1.5708 0 1.5708" />
    <parent
      link="base" />
    <child
      link="FR_hip" />
    <axis
      xyz="0 0 1" />
    <limit
      lower="-3.14159"
      upper="3.14159"
      effort="23"
      velocity="30" />
  </joint>
  <link
    name="FR_thigh">
    <inertial>
      <origin
        xyz="0.0499236644984038 -0.00095533735015299 0.0541375735915618"
        rpy="0 0 0" />
      <mass
        value="1.35333898941377" />
      <inertia
        ixx="0.000674130840947475"
        ixy="-4.10348103171102E-05"
        ixz="7.12447410623136E-08"
        iyy="0.00268403924907943"
        iyz="8.29103687296662E-08"
        izz="0.00329010243857759" />
    </inertial>
    <visual>
      <origin
        xyz="0 0 0"
        rpy="0 0 0" />
      <geometry>
        <mesh
          filename="rf_link2.stl" />
      </geometry>
      <material
        name="">
        <color
          rgba="1 1 1 1" />
      </material>
    </visual>
    <collision>
      <origin
        xyz="0 0 0"
        rpy="0 0 0" />
      <geometry>
        <mesh
          filename="rf_link2.stl" />
      </geometry>
    </collision>
  </link>
  <joint
    name="FR_thigh_joint"
    type="revolute">
    <origin
      xyz="-0.0313 -0.00018614 0.06"
      rpy="1.5708 0 -1.5708" />
    <parent
      link="FR_hip" />
    <child
      link="FR_thigh" />
    <axis
      xyz="0 0 1" />
    <limit
      lower="-3.14159"
      upper="3.14159"
      effort="23"
      velocity="30" />
  </joint>
  <link
    name="FR_calf">
    <inertial>
      <origin
        xyz="0.0837721782388981 -6.26428867112061E-09 -0.000491211466285557"
        rpy="0 0 0" />
      <mass
        value="0.466427846899075" />
      <inertia
        ixx="0.000152426923925918"
        ixy="3.75099629904962E-13"
        ixz="-2.22788171525655E-18"
        iyy="0.00113858892164272"
        iyz="2.321003253702E-20"
        izz="0.00126903700282174" />
    </inertial>
    <visual>
      <origin
        xyz="0 0 0"
        rpy="0 0 0" />
      <geometry>
        <mesh
          filename="rf_link3.stl" />
      </geometry>
      <material
        name="">
        <color
          rgba="0.847058823529412 0.847058823529412 0.847058823529412 1" />
      </material>
    </visual>
    <collision>
      <origin
        xyz="0 0 0"
        rpy="0 0 0" />
      <geometry>
        <mesh
          filename="rf_link3.stl" />
      </geometry>
    </collision>
  </link>
  <joint
    name="FR_calf_joint"
    type="revolute">
    <origin
      xyz="0.20707 -0.0041231 0.0726"
      rpy="0 0 1.5708" />
    <parent
      link="FR_thigh" />
    <child
      link="FR_calf" />
    <axis
      xyz="0 0 1" />
    <limit
      lower="-3.14159"
      upper="3.14159"
      effort="23"
      velocity="30" />
  </joint>
  <link
    name="FR_foot">
    <inertial>
      <origin
        xyz="-1.43280654008038E-09 -0.000378378942221369 3.4596987497082E-09"
        rpy="0 0 0" />
      <mass
        value="0.0848322169853742" />
      <inertia
        ixx="4.13433919259362E-05"
        ixy="1.01643953670516E-20"
        ixz="4.23348081801734E-21"
        iyy="4.1355537203169E-05"
        iyz="2.22118431247219E-20"
        izz="7.44813705583867E-05" />
    </inertial>
    <visual>
      <origin
        xyz="0 0 0"
        rpy="0 0 0" />
      <geometry>
        <mesh
          filename="rf_link4.stl" />
      </geometry>
      <material
        name="">
        <color
          rgba="1 1 1 1" />
      </material>
    </visual>
    <collision>
      <origin
        xyz="0 0 0"
        rpy="0 0 0" />
      <geometry>
        <mesh
          filename="rf_link4.stl" />
      </geometry>
    </collision>
  </link>
  <joint
    name="FR_foot_joint"
    type="fixed">
    <origin
      xyz="0.22 0 0"
      rpy="3.1416 0 -1.5708" />
    <parent
      link="FR_calf" />
    <child
      link="FR_foot" />
    <axis
      xyz="0 0 0" />
  </joint>
  <link
    name="RL_hip">
    <inertial>
      <origin
        xyz="0.00904656350288735 -0.000433656161891323 0.0511411943445323"
        rpy="0 0 0" />
      <mass
        value="0.676831591069983" />
      <inertia
        ixx="0.000670935957278907"
        ixy="6.96734209824113E-08"
        ixz="8.97955632218754E-08"
        iyy="0.000333006407679928"
        iyz="-6.92639255883879E-06"
        izz="0.000392733398463341" />
    </inertial>
    <visual>
      <origin
        xyz="0 0 0"
        rpy="0 0 0" />
      <geometry>
        <mesh
          filename="lb_link1.stl" />
      </geometry>
      <material
        name="">
        <color
          rgba="0.698039215686274 0.698039215686274 0.698039215686274 1" />
      </material>
    </visual>
    <collision>
      <origin
        xyz="0 0 0"
        rpy="0 0 0" />
      <geometry>
        <mesh
          filename="lb_link1.stl" />
      </geometry>
    </collision>
  </link>
  <joint
    name="RL_hip_joint"
    type="revolute">
    <origin
      xyz="-0.20677 0.058639 0.03776"
      rpy="-1.5708 0 1.5708" />
    <parent
      link="base" />
    <child
      link="RL_hip" />
    <axis
      xyz="0 0 1" />
    <limit
      lower="-3.14159"
      upper="3.14159"
      effort="23"
      velocity="30" />
  </joint>
  <link
    name="RL_thigh">
    <inertial>
      <origin
        xyz="0.0472600825732321 3.7200257848452E-05 0.0568578568553258"
        rpy="0 0 0" />
      <mass
        value="1.40828094682296" />
      <inertia
        ixx="0.000744898889098693"
        ixy="-9.97860435592517E-07"
        ixz="6.95820951830706E-08"
        iyy="0.00271564027156907"
        iyz="8.43164123649855E-08"
        izz="0.0033784005109793" />
    </inertial>
    <visual>
      <origin
        xyz="0 0 0"
        rpy="0 0 0" />
      <geometry>
        <mesh
          filename="lb_link2.stl" />
      </geometry>
      <material
        name="">
        <color
          rgba="1 1 1 1" />
      </material>
    </visual>
    <collision>
      <origin
        xyz="0 0 0"
        rpy="0 0 0" />
      <geometry>
        <mesh
          filename="lb_link2.stl" />
      </geometry>
    </collision>
  </link>
  <joint
    name="RL_thigh_joint"
    type="revolute">
    <origin
      xyz="0.029301 -1.3226E-05 0.06"
      rpy="1.5708 0 1.5708" />
    <parent
      link="RL_hip" />
    <child
      link="RL_thigh" />
    <axis
      xyz="0 0 1" />
    <limit
      lower="-3.14159"
      upper="3.14159"
      effort="23"
      velocity="30" />
  </joint>
  <link
    name="RL_calf">
    <inertial>
      <origin
        xyz="0.0837721783440552 -5.40152703121244E-09 -0.000491211466604163"
        rpy="0 0 0" />
      <mass
        value="0.466427846899075" />
      <inertia
        ixx="0.000152426923926207"
        ixy="3.75101093577895E-13"
        ixz="-7.19618628917355E-18"
        iyy="0.00113858892164268"
        iyz="-1.02678728942779E-18"
        izz="0.001269037002822" />
    </inertial>
    <visual>
      <origin
        xyz="0 0 0"
        rpy="0 0 0" />
      <geometry>
        <mesh
          filename="lb_link3.stl" />
      </geometry>
      <material
        name="">
        <color
          rgba="0.847058823529412 0.847058823529412 0.847058823529412 1" />
      </material>
    </visual>
    <collision>
      <origin
        xyz="0 0 0"
        rpy="0 0 0" />
      <geometry>
        <mesh
          filename="lb_link3.stl" />
      </geometry>
    </collision>
  </link>
  <joint
    name="RL_calf_joint"
    type="revolute">
    <origin
      xyz="0.20711 0 0.0746"
      rpy="0 0 -1.570796" />
    <parent
      link="RL_thigh" />
    <child
      link="RL_calf" />
    <axis
      xyz="0 0 1" />
    <limit
      lower="-3.14159"
      upper="3.14159"
      effort="23"
      velocity="30" />
  </joint>
  <link
    name="RL_foot">
    <inertial>
      <origin
        xyz="5.29404853288895E-11 -0.000378375798436359 2.12857509396258E-13"
        rpy="0 0 0" />
      <mass
        value="0.084832216985374" />
      <inertia
        ixx="4.13433919259001E-05"
        ixy="-3.3881317890172E-21"
        ixz="1.45062742863263E-19"
        iyy="4.1355537203133E-05"
        iyz="1.82961458882169E-18"
        izz="7.44813705583866E-05" />
    </inertial>
    <visual>
      <origin
        xyz="0 0 0"
        rpy="0 0 0" />
      <geometry>
        <mesh
          filename="lb_link4.stl" />
      </geometry>
      <material
        name="">
        <color
          rgba="1 1 1 1" />
      </material>
    </visual>
    <collision>
      <origin
        xyz="0 0 0"
        rpy="0 0 0" />
      <geometry>
        <mesh
          filename="lb_link4.stl" />
      </geometry>
    </collision>
  </link>
  <joint
    name="RL_foot_joint"
    type="fixed">
    <origin
      xyz="0.22 0 0"
      rpy="3.1416 0 -1.5708" />
    <parent
      link="RL_calf" />
    <child
      link="RL_foot" />
    <axis
      xyz="0 0 0" />
  </joint>
  <link
    name="RR_hip">
    <inertial>
      <origin
        xyz="-0.00904656350288724 0.000534630482668015 0.0509865912088688"
        rpy="0 0 0" />
      <mass
        value="0.676831591069986" />
      <inertia
        ixx="0.000670935957278905"
        ixy="-6.94811296374778E-08"
        ixz="7.88086818711052E-08"
        iyy="0.000333006407679927"
        iyz="6.92639255884089E-06"
        izz="0.00039273339846334" />
    </inertial>
    <visual>
      <origin
        xyz="0 0 0"
        rpy="0 0 0" />
      <geometry>
        <mesh
          filename="rb_link1.stl" />
      </geometry>
      <material
        name="">
        <color
          rgba="0.698039215686274 0.698039215686274 0.698039215686274 1" />
      </material>
    </visual>
    <collision>
      <origin
        xyz="0 0 0"
        rpy="0 0 0" />
      <geometry>
        <mesh
          filename="rb_link1.stl" />
      </geometry>
    </collision>
  </link>
  <joint
    name="RR_hip_joint"
    type="revolute">
    <origin
      xyz="-0.20677 -0.06136 0.037786"
      rpy="-1.5708 0 1.5708" />
    <parent
      link="base" />
    <child
      link="RR_hip" />
    <axis
      xyz="0 0 1" />
    <limit
      lower="-3.14159"
      upper="3.14159"
      effort="23"
      velocity="30" />
  </joint>
  <link
    name="RR_thigh">
    <inertial>
      <origin
        xyz="0.0499327884362379 3.87095578488206E-05 0.0561375736632924"
        rpy="0 0 0" />
      <mass
        value="1.35333899025955" />
      <inertia
        ixx="0.000673293902165864"
        ixy="-9.97865570015108E-07"
        ixz="6.95772954651588E-08"
        iyy="0.00268487617008975"
        iyz="8.4302097082855E-08"
        izz="0.00329010242027444" />
    </inertial>
    <visual>
      <origin
        xyz="0 0 0"
        rpy="0 0 0" />
      <geometry>
        <mesh
          filename="rb_link2.stl" />
      </geometry>
      <material
        name="">
        <color
          rgba="0.847058823529412 0.847058823529412 0.847058823529412 1" />
      </material>
    </visual>
    <collision>
      <origin
        xyz="0 0 0"
        rpy="0 0 0" />
      <geometry>
        <mesh
          filename="rb_link2.stl" />
      </geometry>
    </collision>
  </link>
  <joint
    name="RR_thigh_joint"
    type="revolute">
    <origin
      xyz="-0.029301 1.3226E-05 0.06"
      rpy="-1.5708 0 1.5708" />
    <parent
      link="RR_hip" />
    <child
      link="RR_thigh" />
    <axis
      xyz="0 0 1" />
    <limit
      lower="-3.14159"
      upper="3.14159"
      effort="23"
      velocity="30" />
  </joint>
  <link
    name="RR_calf">
    <inertial>
      <origin
        xyz="0.0855640092589884 -5.44242703681697E-09 -0.000917147224226089"
        rpy="0 0 0" />
      <mass
        value="0.456660190803704" />
      <inertia
        ixx="0.00015159947628157"
        ixy="3.91459928979643E-13"
        ixz="1.350538504931E-18"
        iyy="0.00113776147399772"
        iyz="3.328830290636E-19"
        izz="0.00126764703085159" />
    </inertial>
    <visual>
      <origin
        xyz="0 0 0"
        rpy="0 0 0" />
      <geometry>
        <mesh
          filename="rb_link3.stl" />
      </geometry>
      <material
        name="">
        <color
          rgba="0.847058823529412 0.847058823529412 0.847058823529412 1" />
      </material>
    </visual>
    <collision>
      <origin
        xyz="0 0 0"
        rpy="0 0 0" />
      <geometry>
        <mesh
          filename="rb_link3.stl" />
      </geometry>
    </collision>
  </link>
  <joint
    name="RR_calf_joint"
    type="revolute">
    <origin
      xyz="0.20711 0 0.0746"
      rpy="0 0 1.570796" />
    <parent
      link="RR_thigh" />
    <child
      link="RR_calf" />
    <axis
      xyz="0 0 1" />
    <limit
      lower="-3.14159"
      upper="3.14159"
      effort="23"
      velocity="30" />
  </joint>
  <link
    name="RR_foot">
    <inertial>
      <origin
        xyz="-2.20403631456811E-09 -0.000378377603562075 7.82278797295533E-10"
        rpy="0 0 0" />
      <mass
        value="0.084832216985374" />
      <inertia
        ixx="4.13433919258284E-05"
        ixy="-1.93631731742333E-18"
        ixz="1.25883569819351E-19"
        iyy="4.13555372030613E-05"
        iyz="-1.22192788075616E-18"
        izz="7.44813705583866E-05" />
    </inertial>
    <visual>
      <origin
        xyz="0 0 0"
        rpy="0 0 0" />
      <geometry>
        <mesh
          filename="rb_link4.stl" />
      </geometry>
      <material
        name="">
        <color
          rgba="1 1 1 1" />
      </material>
    </visual>
    <collision>
      <origin
        xyz="0 0 0"
        rpy="0 0 0" />
      <geometry>
        <mesh
          filename="rb_link4.stl" />
      </geometry>
    </collision>
  </link>
  <joint
    name="RR_foot_joint"
    type="fixed">
    <origin
      xyz="0.22 0 0"
      rpy="3.1416 0 -1.5708" />
    <parent
      link="RR_calf" />
    <child
      link="RR_foot" />
    <axis
      xyz="0 0 0" />
  </joint>
</robot>